<mujoco model="Pikachu_V025">
    <compiler angle="radian" meshdir="../meshes/" />
    <size njmax="500" nconmax="100" />
    
    
        <include file="scene.xml"/>
    <asset>
        <mesh name="base_link" file="base_link.STL" />
        <mesh name="left_hip_pitch_link" file="left_hip_pitch_link.STL" />
        <mesh name="left_hip_roll_link" file="left_hip_roll_link.STL" />
        <mesh name="left_hip_yaw_link" file="left_hip_yaw_link.STL" />
        <mesh name="left_knee_link" file="left_knee_link.STL" />
        <mesh name="left_ankle_link" file="left_ankle_link.STL" />
        <mesh name="right_hip_pitch_link" file="right_hip_pitch_link.STL" />
        <mesh name="right_hip_roll_link" file="right_hip_roll_link.STL" />
        <mesh name="right_hip_yaw_link" file="right_hip_yaw_link.STL" />
        <mesh name="right_knee_link" file="right_knee_link.STL" />
        <mesh name="right_ankle_link" file="right_ankle_link.STL" />
        <mesh name="left_arm_pitch_link" file="left_arm_pitch_link.STL" />
        <mesh name="left_arm_roll_link" file="left_arm_roll_link.STL" />
        <mesh name="left_arm_yaw_link" file="left_arm_yaw_link.STL" />
        <mesh name="left_elbow_link" file="left_elbow_link.STL" />
        <mesh name="right_arm_pitch_link" file="right_arm_pitch_link.STL" />
        <mesh name="right_arm_roll_link" file="right_arm_roll_link.STL" />
        <mesh name="right_arm_yaw_link" file="right_arm_yaw_link.STL" />
        <mesh name="right_elbow_link" file="right_elbow_link.STL" />
    </asset>
    <worldbody>
        <body name="base_link" pos="0 0 0">
            <inertial pos="-0.0248659 -0.000239075 0.10428" quat="0.710649 -0.0251612 -0.0252497 0.702643" mass="1.51846" diaginertia="0.00263554 0.00237184 0.00139589" />
            <geom type="mesh" contype="0" conaffinity="0" group="1" rgba="0.792157 0.819608 0.933333 1" mesh="base_link" />
            <geom type="mesh" rgba="0.792157 0.819608 0.933333 1" mesh="base_link" />
            <body name="left_hip_pitch_link" pos="0 0.0515 0">
                <inertial pos="0.00920325 0.0289511 0.0244534" quat="0.986737 -0.161982 -0.0046624 -0.00951114" mass="0.131128" diaginertia="3.09449e-05 3.02338e-05 2.40386e-05" />
                <joint name="left_hip_pitch_joint" pos="0 0 0" axis="0 -1 0" limited="true" range="-1.05 1.75" damping="0.4" frictionloss="0.01" />
                <geom type="mesh" contype="0" conaffinity="0" group="1" rgba="0.898039 0.917647 0.929412 1" mesh="left_hip_pitch_link" />
                <geom type="mesh" rgba="0.898039 0.917647 0.929412 1" mesh="left_hip_pitch_link" />
                <body name="left_hip_roll_link" pos="0 0.0355 0">
                    <inertial pos="-2.06148e-05 0.0257689 -0.0109486" quat="0.517296 0.482196 -0.483543 0.515828" mass="0.12046" diaginertia="2.98445e-05 2.63363e-05 2.39739e-05" />
                    <joint name="left_hip_roll_joint" pos="0 0 0" axis="1 0 0" limited="true" range="-0.09 0.26" damping="0.15" frictionloss="0.01" />
                    <geom type="mesh" contype="0" conaffinity="0" group="1" rgba="0.647059 0.619608 0.588235 1" mesh="left_hip_roll_link" />
                    <geom type="mesh" rgba="0.647059 0.619608 0.588235 1" mesh="left_hip_roll_link" />
                    <body name="left_hip_yaw_link" pos="0 0 -0.046">
                        <inertial pos="-0.00163504 0.000676763 0.0166627" quat="0.996873 0.0790221 5.30087e-06 -5.09339e-07" mass="0.0410649" diaginertia="1.77922e-05 1.32249e-05 7.20812e-06" />
                        <joint name="left_hip_yaw_joint" pos="0 0 0" axis="0 0 1" limited="true" range="-0.09 0.26" damping="0.15" frictionloss="0.01" />
                        <geom type="mesh" contype="0" conaffinity="0" group="1" rgba="0.698039 0.698039 0.698039 1" mesh="left_hip_yaw_link" />
                        <geom type="mesh" rgba="0.698039 0.698039 0.698039 1" mesh="left_hip_yaw_link" />
                        <body name="left_knee_link" pos="0 0 -0.025">
                            <inertial pos="7.33451e-06 0.0238047 -0.0335203" quat="0.999976 0.00530318 0.00375 -0.00223969" mass="0.218032" diaginertia="8.40377e-05 8.32282e-05 7.04001e-05" />
                            <joint name="left_knee_joint" pos="0 0 0" axis="0 1 0" limited="true" range="0 1.57" damping="0.15" frictionloss="0.01" />
                            <geom type="mesh" contype="0" conaffinity="0" group="1" rgba="0.792157 0.819608 0.933333 1" mesh="left_knee_link" />
                            <geom type="mesh" rgba="0.792157 0.819608 0.933333 1" mesh="left_knee_link" />
                            <body name="left_ankle_link" pos="0 0 -0.07">
                                <inertial pos="-0.0136093 0.0198623 -0.0300854" quat="-0.0361985 0.714091 0.0862009 0.693782" mass="0.135141" diaginertia="0.000101267 8.39665e-05 6.61664e-05" />
                                <joint name="left_ankle_joint" pos="0 0 0" axis="0 -1 0" limited="true" range="-0.52 1.05" damping="0.4" frictionloss="0.01" />
                                <geom type="mesh" contype="0" conaffinity="0" group="1" rgba="0.698039 0.698039 0.698039 1" mesh="left_ankle_link" />
                                <geom type="mesh" rgba="0.698039 0.698039 0.698039 1" mesh="left_ankle_link" />
                            </body>
                        </body>
                    </body>
                </body>
            </body>
            <body name="right_hip_pitch_link" pos="0 -0.0515 0">
                <inertial pos="-0.00920325 -0.0289511 0.0244534" quat="0.986737 0.161982 0.0046624 -0.00951114" mass="0.131128" diaginertia="3.09449e-05 3.02338e-05 2.40386e-05" />
                <joint name="right_hip_pitch_joint" pos="0 0 0" axis="0 -1 0" limited="true" range="-1.05 1.75" damping="0.4" frictionloss="0.01" />
                <geom type="mesh" contype="0" conaffinity="0" group="1" rgba="1 1 1 1" mesh="right_hip_pitch_link" />
                <geom type="mesh" rgba="1 1 1 1" mesh="right_hip_pitch_link" />
                <body name="right_hip_roll_link" pos="0 -0.0355 0">
                    <inertial pos="-0.00014211 -0.0257568 -0.0109486" quat="0.500304 0.502409 -0.530351 0.464766" mass="0.12046" diaginertia="2.98448e-05 2.63244e-05 2.39855e-05" />
                    <joint name="right_hip_roll_joint" pos="0 0 0" axis="-1 0 0" limited="true" range="-0.09 0.26" damping="0.15" frictionloss="0.01" />
                    <geom type="mesh" contype="0" conaffinity="0" group="1" rgba="0.647059 0.619608 0.588235 1" mesh="right_hip_roll_link" />
                    <geom type="mesh" rgba="0.647059 0.619608 0.588235 1" mesh="right_hip_roll_link" />
                    <body name="right_hip_yaw_link" pos="0 0 -0.046">
                        <inertial pos="0.00163504 -0.000676764 0.0166627" quat="0.996873 -0.0790221 -5.3016e-06 -4.84862e-07" mass="0.0410649" diaginertia="1.77922e-05 1.32249e-05 7.20812e-06" />
                        <joint name="right_hip_yaw_joint" pos="0 0 0" axis="0 0 -1" limited="true" range="-0.09 0.26" damping="0.15" frictionloss="0.01" />
                        <geom type="mesh" contype="0" conaffinity="0" group="1" rgba="0.698039 0.698039 0.698039 1" mesh="right_hip_yaw_link" />
                        <geom type="mesh" rgba="0.698039 0.698039 0.698039 1" mesh="right_hip_yaw_link" />
                        <body name="right_knee_link" pos="0 0 -0.025">
                            <inertial pos="-7.33451e-06 -0.0238047 -0.0335203" quat="0.999976 -0.00530318 -0.00375006 -0.0022397" mass="0.218032" diaginertia="8.40377e-05 8.32282e-05 7.04001e-05" />
                            <joint name="right_knee_joint" pos="0 0 0" axis="0 1 0" limited="true" range="0 1.57" damping="0.4" frictionloss="0.01" />
                            <geom type="mesh" contype="0" conaffinity="0" group="1" rgba="0.792157 0.819608 0.933333 1" mesh="right_knee_link" />
                            <geom type="mesh" rgba="0.792157 0.819608 0.933333 1" mesh="right_knee_link" />
                            <body name="right_ankle_link" pos="0 0 -0.07">
                                <inertial pos="0.0136093 -0.0198623 -0.0300855" quat="-0.0862009 0.693782 0.0361984 0.714091" mass="0.135141" diaginertia="0.000101267 8.39665e-05 6.61664e-05" />
                                <joint name="right_ankle_joint" pos="0 0 0" axis="0 1 0" limited="true" range="-0.52 1.05" damping="0.15" frictionloss="0.01" />
                                <geom type="mesh" contype="0" conaffinity="0" group="1" rgba="1 1 1 1" mesh="right_ankle_link" />
                                <geom type="mesh" rgba="1 1 1 1" mesh="right_ankle_link" />
                            </body>
                        </body>
                    </body>
                </body>
            </body>
            <body name="left_arm_pitch_link" pos="0 0.0515 0.2">
                <inertial pos="0.00573527 0.0343503 0.0197089" quat="0.705563 -0.047721 0.0487218 0.705358" mass="0.157018" diaginertia="4.35632e-05 3.80987e-05 3.25772e-05" />
                <geom type="mesh" contype="0" conaffinity="0" group="1" rgba="0.898039 0.917647 0.929412 1" mesh="left_arm_pitch_link" />
                <geom type="mesh" rgba="0.898039 0.917647 0.929412 1" mesh="left_arm_pitch_link" />
                <body name="left_arm_roll_link" pos="0 0.049 0">
                    <inertial pos="4.99148e-05 -0.00641433 -0.0240058" quat="0.704417 -0.02096 0.0211293 0.709163" mass="0.021192" diaginertia="1.02964e-05 1.00982e-05 5.84058e-06" />
                    <geom type="mesh" contype="0" conaffinity="0" group="1" rgba="1 0.945098 0.513726 1" mesh="left_arm_roll_link" />
                    <geom type="mesh" rgba="1 0.945098 0.513726 1" mesh="left_arm_roll_link" />
                    <body name="left_arm_yaw_link" pos="5e-05 0 -0.051">
                        <inertial pos="0.00210962 0.00808711 -0.0186517" quat="0.863113 0.503728 -0.035893 -0.0022746" mass="0.0245464" diaginertia="1.16361e-05 1.04086e-05 8.25893e-06" />
                        <geom type="mesh" contype="0" conaffinity="0" group="1" rgba="0.698039 0.698039 0.698039 1" mesh="left_arm_yaw_link" />
                        <geom type="mesh" rgba="0.698039 0.698039 0.698039 1" mesh="left_arm_yaw_link" />
                        <body name="left_elbow_link" pos="0 0 -0.021" quat="0.707388 0 -0.706825 0">
                            <inertial pos="0 0.00793438 -0.0327214" quat="0.444887 0.895587 0 0" mass="0.0144259" diaginertia="1.41116e-05 9.27482e-06 6.18903e-06" />
                            <geom type="mesh" contype="0" conaffinity="0" group="1" rgba="0.698039 0.698039 0.698039 1" mesh="left_elbow_link" />
                            <geom type="mesh" rgba="0.698039 0.698039 0.698039 1" mesh="left_elbow_link" />
                        </body>
                    </body>
                </body>
            </body>
            <body name="right_arm_pitch_link" pos="0 -0.0515 0.2">
                <inertial pos="-0.00573527 -0.0343503 0.0197089" quat="0.705563 0.047721 -0.0487218 0.705358" mass="0.157018" diaginertia="4.35632e-05 3.80987e-05 3.25772e-05" />
                <geom type="mesh" contype="0" conaffinity="0" group="1" rgba="1 1 1 1" mesh="right_arm_pitch_link" />
                <geom type="mesh" rgba="1 1 1 1" mesh="right_arm_pitch_link" />
                <body name="right_arm_roll_link" pos="0 -0.049 0">
                    <inertial pos="-4.99148e-05 0.00641433 -0.0240058" quat="0.704417 0.02096 -0.0211293 0.709163" mass="0.021192" diaginertia="1.02964e-05 1.00982e-05 5.84058e-06" />
                    <geom type="mesh" contype="0" conaffinity="0" group="1" rgba="1 0.945098 0.513726 1" mesh="right_arm_roll_link" />
                    <geom type="mesh" rgba="1 0.945098 0.513726 1" mesh="right_arm_roll_link" />
                    <body name="right_arm_yaw_link" pos="-5e-05 0 -0.051">
                        <inertial pos="-0.00210962 -0.00808711 -0.0186517" quat="0.503728 0.863113 -0.0022746 -0.035893" mass="0.0245464" diaginertia="1.16361e-05 1.04086e-05 8.25893e-06" />
                        <geom type="mesh" contype="0" conaffinity="0" group="1" rgba="0.698039 0.698039 0.698039 1" mesh="right_arm_yaw_link" />
                        <geom type="mesh" rgba="0.698039 0.698039 0.698039 1" mesh="right_arm_yaw_link" />
                        <body name="right_elbow_link" pos="0 0 -0.021" quat="0.707388 0 -0.706825 0">
                            <inertial pos="0 -0.00793438 -0.0327214" quat="0.895587 0.444887 0 0" mass="0.0144259" diaginertia="1.41116e-05 9.27482e-06 6.18903e-06" />
                            <geom type="mesh" contype="0" conaffinity="0" group="1" rgba="0.698039 0.698039 0.698039 1" mesh="right_elbow_link" />
                            <geom type="mesh" rgba="0.698039 0.698039 0.698039 1" mesh="right_elbow_link" />
                        </body>
                    </body>
                </body>
            </body>
        </body>
    </worldbody>
</mujoco>
